Workbook

Sheet Scenario
A1: Setting | B1: Value
A2: Scenario | B2: Pre-Roxanne: encounters through Route 116
A3: Generated | B3: 2026-08-17T11:15:23
A4: Dex snapshot | B4: C:\Users\prana\Downloads\Decomps\romhack-docs\public\data\dex.json
A5: Dex generatedAt | B5: 2026-08-06T05:10:42.544Z
A6: Google Sheet | B6: https://docs.google.com/spreadsheets/d/1hdZdmDTvVAbuoer8FHvYYZAVdjp9NGGppLklhBIi62w/edit
A7: Level cap / player level | B7: 15
A8: Player Nature mode | B8: fixed: Neutral
A9: Player Ability mode | B9: first
A10: Move ranking metric | B10: expected
A11: Weather | B11: None
A12: Terrain | B12: None
A13: Included maps | B13: MAP_ROUTE101, MAP_ROUTE103, MAP_ROUTE102, MAP_ROUTE104, MAP_PETALBURG_WOODS, MAP_ROUTE116
A14: Included encounter methods | B14: Land, Sand
A15: Excluded prerequisite moves | B15: MOVE_BELCH
A16: Player species/forms analyzed | B16: 32
A17: Boss | B17: Roxanne (Fossil draft)
A18: Target | B18: Lileep Lv. 15
A19: Boss attacker | B19: Lileep Lv. 15
A20: Important | B20: Empty boss move lists use all legal level-up moves. Enter exact trainers.party moves before treating boss offense as final.

Sheet Threshold Summary
A1: Pokémon | B1: Best outgoing move | C1: Outgoing avg % | D1: Strongest incoming move | E1: Incoming avg % | F1: Player Spe | G1: Boss Spe | H1: Outspeeds? | I1: Net score | J1: Rating | K1: Species ID | L1: Level | M1: Nature | N1: Ability | O1: HP EV | P1: Atk EV | Q1: Def EV | R1: SpA EV | S1: SpD EV | T1: Spe EV | U1: Outgoing min | V1: Outgoing max | W1: Incoming min | X1: Incoming max | Y1: Origin Species ID | Z1: Move override
A2: =XLOOKUP(K2,'Pokemon Editor'!$A:$A,'Pokemon Editor'!$B:$B,K2) | B2: =IF($Z2<>"",$Z2,IFERROR(INDEX(FILTER('Move Comparison'!$D$2:$D,'Move Comparison'!$Q$2:$Q=$Y2,'Move Comparison'!$M$2:$M=MAXIFS('Move Comparison'!$M$2:$M,'Move Comparison'!$Q$2:$Q,$Y2),'Move Comparison'!$D$2:$D<>""),1),"")) | C2: =IFERROR(LET(mtype,XLOOKUP($B2,'Move Editor'!$B:$B,'Move Editor'!$C:$C,""),cat,XLOOKUP($B2,'Move Editor'!$B:$B,'Move Editor'!$D:$D,""),pow,XLOOKUP($B2,'Move Editor'!$B:$B,'Move Editor'!$E:$E,0),acc,XLOOKUP($B2,'Move Editor'!$B:$B,'Move Editor'!$F:$F,100),atk,IF(cat="Physical",FLOOR((FLOOR(((2*XLOOKUP($K2,'Pokemon Editor'!$A:$A,'Pokemon Editor'!$F:$F,0)+31+FLOOR($P2/4))*$L2)/100)+5)*XLOOKUP($M2,'Nature Editor'!$A:$A,'Nature Editor'!$B:$B,1)),FLOOR((FLOOR(((2*XLOOKUP($K2,'Pokemon Editor'!$A:$A,'Pokemon Editor'!$H:$H,0)+31+FLOOR($R2/4))*$L2)/100)+5)*XLOOKUP($M2,'Nature Editor'!$A:$A,'Nature Editor'!$D:$D,1))),def,IF(cat="Physical",FLOOR((FLOOR(((2*XLOOKUP('Boss Editor'!$C$4,'Pokemon Editor'!$A:$A,'Pokemon Editor'!$G:$G,0)+31+FLOOR('Boss Editor'!$I$4/4))*'Boss Editor'!$D$4)/100)+5)*XLOOKUP('Boss Editor'!$E$4,'Nature Editor'!$A:$A,'Nature Editor'!$C:$C,1)),FLOOR((FLOOR(((2*XLOOKUP('Boss Editor'!$C$4,'Pokemon Editor'!$A:$A,'Pokemon Editor'!$I:$I,0)+31+FLOOR('Boss Editor'!$K$4/4))*'Boss Editor'!$D$4)/100)+5)*XLOOKUP('Boss Editor'!$E$4,'Nature Editor'!$A:$A,'Nature Editor'!$E:$E,1))),stab,IF(OR(mtype=XLOOKUP($K2,'Pokemon Editor'!$A:$A,'Pokemon Editor'!$C:$C,""),mtype=XLOOKUP($K2,'Pokemon Editor'!$A:$A,'Pokemon Editor'!$D:$D,"")),1.5,1),eff,(INDEX('Type Chart'!$B:$S,MATCH(mtype,'Type Chart'!$A:$A,0),MATCH(XLOOKUP('Boss Editor'!$C$4,'Pokemon Editor'!$A:$A,'Pokemon Editor'!$C:$C,""),'Type Chart'!$B$1:$S$1,0))*IF(XLOOKUP('Boss Editor'!$C$4,'Pokemon Editor'!$A:$A,'Pokemon Editor'!$D:$D,"")="",1,INDEX('Type Chart'!$B:$S,MATCH(mtype,'Type Chart'!$A:$A,0),MATCH(XLOOKUP('Boss Editor'!$C$4,'Pokemon Editor'!$A:$A,'Pokemon Editor'!$D:$D,""),'Type Chart'!$B$1:$S$1,0)))),base,IF(OR(cat="Status",pow=0),0,FLOOR(FLOOR(FLOOR((2*$L2/5+2)*pow*atk/def)/50)+2)),modifier,stab*eff,AVERAGE(ARRAYFORMULA(FLOOR(base*modifier*SEQUENCE(16,1,85,1)/100)))/(FLOOR(((2*XLOOKUP('Boss Editor'!$C$4,'Pokemon Editor'!$A:$A,'Pokemon Editor'!$E:$E,0)+31+FLOOR('Boss Editor'!$G$4/4))*'Boss Editor'!$D$4)/100)+'Boss Editor'!$D$4+10)),0) | D2: Acid | E2: =IFERROR(LET(mtype,XLOOKUP($D2,'Move Editor'!$B:$B,'Move Editor'!$C:$C,""),cat,XLOOKUP($D2,'Move Editor'!$B:$B,'Move Editor'!$D:$D,""),pow,XLOOKUP($D2,'Move Editor'!$B:$B,'Move Editor'!$E:$E,0),acc,XLOOKUP($D2,'Move Editor'!$B:$B,'Move Editor'!$F:$F,100),atk,IF(cat="Physical",FLOOR((FLOOR(((2*XLOOKUP('Boss Editor'!$C$4,'Pokemon Editor'!$A:$A,'Pokemon Editor'!$F:$F,0)+31+FLOOR('Boss Editor'!$H$4/4))*'Boss Editor'!$D$4)/100)+5)*XLOOKUP('Boss Editor'!$E$4,'Nature Editor'!$A:$A,'Nature Editor'!$B:$B,1)),FLOOR((FLOOR(((2*XLOOKUP('Boss Editor'!$C$4,'Pokemon Editor'!$A:$A,'Pokemon Editor'!$H:$H,0)+31+FLOOR('Boss Editor'!$J$4/4))*'Boss Editor'!$D$4)/100)+5)*XLOOKUP('Boss Editor'!$E$4,'Nature Editor'!$A:$A,'Nature Editor'!$D:$D,1))),def,IF(cat="Physical",FLOOR((FLOOR(((2*XLOOKUP($K2,'Pokemon Editor'!$A:$A,'Pokemon Editor'!$G:$G,0)+31+FLOOR($Q2/4))*$L2)/100)+5)*XLOOKUP($M2,'Nature Editor'!$A:$A,'Nature Editor'!$C:$C,1)),FLOOR((FLOOR(((2*XLOOKUP($K2,'Pokemon Editor'!$A:$A,'Pokemon Editor'!$I:$I,0)+31+FLOOR($S2/4))*$L2)/100)+5)*XLOOKUP($M2,'Nature Editor'!$A:$A,'Nature Editor'!$E:$E,1))),stab,IF(OR(mtype=XLOOKUP('Boss Editor'!$C$4,'Pokemon Editor'!$A:$A,'Pokemon Editor'!$C:$C,""),mtype=XLOOKUP('Boss Editor'!$C$4,'Pokemon Editor'!$A:$A,'Pokemon Editor'!$D:$D,"")),1.5,1),eff,(INDEX('Type Chart'!$B:$S,MATCH(mtype,'Type Chart'!$A:$A,0),MATCH(XLOOKUP($K2,'Pokemon Editor'!$A:$A,'Pokemon Editor'!$C:$C,""),'Type Chart'!$B$1:$S$1,0))*IF(XLOOKUP($K2,'Pokemon Editor'!$A:$A,'Pokemon Editor'!$D:$D,"")="",1,INDEX('Type Chart'!$B:$S,MATCH(mtype,'Type Chart'!$A:$A,0),MATCH(XLOOKUP($K2,'Pokemon Editor'!$A:$A,'Pokemon Editor'!$D:$D,""),'Type Chart'!$B$1:$S$1,0)))),base,IF(OR(cat="Status",pow=0),0,FLOOR(FLOOR(FLOOR((2*'Boss Editor'!$D$4/5+2)*pow*atk/def)/50)+2)),modifier,stab*eff,AVERAGE(ARRAYFORMULA(FLOOR(base*modifier*SEQUENCE(16,1,85,1)/100)))/(FLOOR(((2*XLOOKUP($K2,'Pokemon Editor'!$A:$A,'Pokemon Editor'!$E:$E,0)+31+FLOOR($O2/4))*$L2)/100)+$L2+10)),0) | F2: =FLOOR((FLOOR(((2*XLOOKUP($K2,'Pokemon Editor'!$A:$A,'Pokemon Editor'!$J:$J,0)+31+FLOOR($T2/4))*$L2)/100)+5)*XLOOKUP($M2,'Nature Editor'!$A:$A,'Nature Editor'!$F:$F,1)) | G2: =FLOOR((FLOOR(((2*XLOOKUP('Boss Editor'!$C$4,'Pokemon Editor'!$A:$A,'Pokemon Editor'!$J:$J,0)+31+FLOOR('Boss Editor'!$L$4/4))*'Boss Editor'!$D$4)/100)+5)*XLOOKUP('Boss Editor'!$E$4,'Nature Editor'!$A:$A,'Nature Editor'!$F:$F,1)) | H2: =IF(F2>G2,"Yes","No") | I2: =C2-E2 | J2: =IFS(AND(C2>=0.5,E2<0.5),"Dominant",AND(C2>=0.35,E2<0.75),"Strong",AND(C2>=0.25,E2<1),"Viable",AND(C2>=0.15,E2<1.25),"Risky",TRUE,"Poor") | K2: =REDUCE($Y2,SEQUENCE(2),LAMBDA(current_species,unused_step,IFERROR(INDEX(FILTER('Evolution Editor'!$D$2:$D,'Evolution Editor'!$A$2:$A=current_species,'Evolution Editor'!$F$2:$F=TRUE,'Evolution Editor'!$E$2:$E<=$L2),1),current_species))) | L2: 15 | M2: Neutral | N2: ABILITY_IRON_FIST | O2: 0 | P2: 0 | Q2: 0 | R2: 0 | S2: 0 | T2: 0 | U2: =IFERROR(LET(mtype,XLOOKUP($B2,'Move Editor'!$B:$B,'Move Editor'!$C:$C,""),cat,XLOOKUP($B2,'Move Editor'!$B:$B,'Move Editor'!$D:$D,""),pow,XLOOKUP($B2,'Move Editor'!$B:$B,'Move Editor'!$E:$E,0),acc,XLOOKUP($B2,'Move Editor'!$B:$B,'Move Editor'!$F:$F,100),atk,IF(cat="Physical",FLOOR((FLOOR(((2*XLOOKUP($K2,'Pokemon Editor'!$A:$A,'Pokemon Editor'!$F:$F,0)+31+FLOOR($P2/4))*$L2)/100)+5)*XLOOKUP($M2,'Nature Editor'!$A:$A,'Nature Editor'!$B:$B,1)),FLOOR((FLOOR(((2*XLOOKUP($K2,'Pokemon Editor'!$A:$A,'Pokemon Editor'!$H:$H,0)+31+FLOOR($R2/4))*$L2)/100)+5)*XLOOKUP($M2,'Nature Editor'!$A:$A,'Nature Editor'!$D:$D,1))),def,IF(cat="Physical",FLOOR((FLOOR(((2*XLOOKUP('Boss Editor'!$C$4,'Pokemon Editor'!$A:$A,'Pokemon Editor'!$G:$G,0)+31+FLOOR('Boss Editor'!$I$4/4))*'Boss Editor'!$D$4)/100)+5)*XLOOKUP('Boss Editor'!$E$4,'Nature Editor'!$A:$A,'Nature Editor'!$C:$C,1)),FLOOR((FLOOR(((2*XLOOKUP('Boss Editor'!$C$4,'Pokemon Editor'!$A:$A,'Pokemon Editor'!$I:$I,0)+31+FLOOR('Boss Editor'!$K$4/4))*'Boss Editor'!$D$4)/100)+5)*XLOOKUP('Boss Editor'!$E$4,'Nature Editor'!$A:$A,'Nature Editor'!$E:$E,1))),stab,IF(OR(mtype=XLOOKUP($K2,'Pokemon Editor'!$A:$A,'Pokemon Editor'!$C:$C,""),mtype=XLOOKUP($K2,'Pokemon Editor'!$A:$A,'Pokemon Editor'!$D:$D,"")),1.5,1),eff,(INDEX('Type Chart'!$B:$S,MATCH(mtype,'Type Chart'!$A:$A,0),MATCH(XLOOKUP('Boss Editor'!$C$4,'Pokemon Editor'!$A:$A,'Pokemon Editor'!$C:$C,""),'Type Chart'!$B$1:$S$1,0))*IF(XLOOKUP('Boss Editor'!$C$4,'Pokemon Editor'!$A:$A,'Pokemon Editor'!$D:$D,"")="",1,INDEX('Type Chart'!$B:$S,MATCH(mtype,'Type Chart'!$A:$A,0),MATCH(XLOOKUP('Boss Editor'!$C$4,'Pokemon Editor'!$A:$A,'Pokemon Editor'!$D:$D,""),'Type Chart'!$B$1:$S$1,0)))),base,IF(OR(cat="Status",pow=0),0,FLOOR(FLOOR(FLOOR((2*$L2/5+2)*pow*atk/def)/50)+2)),modifier,stab*eff,FLOOR(base*modifier*0.85)),0) | V2: =IFERROR(LET(mtype,XLOOKUP($B2,'Move Editor'!$B:$B,'Move Editor'!$C:$C,""),cat,XLOOKUP($B2,'Move Editor'!$B:$B,'Move Editor'!$D:$D,""),pow,XLOOKUP($B2,'Move Editor'!$B:$B,'Move Editor'!$E:$E,0),acc,XLOOKUP($B2,'Move Editor'!$B:$B,'Move Editor'!$F:$F,100),atk,IF(cat="Physical",FLOOR((FLOOR(((2*XLOOKUP($K2,'Pokemon Editor'!$A:$A,'Pokemon Editor'!$F:$F,0)+31+FLOOR($P2/4))*$L2)/100)+5)*XLOOKUP($M2,'Nature Editor'!$A:$A,'Nature Editor'!$B:$B,1)),FLOOR((FLOOR(((2*XLOOKUP($K2,'Pokemon Editor'!$A:$A,'Pokemon Editor'!$H:$H,0)+31+FLOOR($R2/4))*$L2)/100)+5)*XLOOKUP($M2,'Nature Editor'!$A:$A,'Nature Editor'!$D:$D,1))),def,IF(cat="Physical",FLOOR((FLOOR(((2*XLOOKUP('Boss Editor'!$C$4,'Pokemon Editor'!$A:$A,'Pokemon Editor'!$G:$G,0)+31+FLOOR('Boss Editor'!$I$4/4))*'Boss Editor'!$D$4)/100)+5)*XLOOKUP('Boss Editor'!$E$4,'Nature Editor'!$A:$A,'Nature Editor'!$C:$C,1)),FLOOR((FLOOR(((2*XLOOKUP('Boss Editor'!$C$4,'Pokemon Editor'!$A:$A,'Pokemon Editor'!$I:$I,0)+31+FLOOR('Boss Editor'!$K$4/4))*'Boss Editor'!$D$4)/100)+5)*XLOOKUP('Boss Editor'!$E$4,'Nature Editor'!$A:$A,'Nature Editor'!$E:$E,1))),stab,IF(OR(mtype=XLOOKUP($K2,'Pokemon Editor'!$A:$A,'Pokemon Editor'!$C:$C,""),mtype=XLOOKUP($K2,'Pokemon Editor'!$A:$A,'Pokemon Editor'!$D:$D,"")),1.5,1),eff,(INDEX('Type Chart'!$B:$S,MATCH(mtype,'Type Chart'!$A:$A,0),MATCH(XLOOKUP('Boss Editor'!$C$4,'Pokemon Editor'!$A:$A,'Pokemon Editor'!$C:$C,""),'Type Chart'!$B$1:$S$1,0))*IF(XLOOKUP('Boss Editor'!$C$4,'Pokemon Editor'!$A:$A,'Pokemon Editor'!$D:$D,"")="",1,INDEX('Type Chart'!$B:$S,MATCH(mtype,'Type Chart'!$A:$A,0),MATCH(XLOOKUP('Boss Editor'!$C$4,'Pokemon Editor'!$A:$A,'Pokemon Editor'!$D:$D,""),'Type Chart'!$B$1:$S$1,0)))),base,IF(OR(cat="Status",pow=0),0,FLOOR(FLOOR(FLOOR((2*$L2/5+2)*pow*atk/def)/50)+2)),modifier,stab*eff,FLOOR(base*modifier)),0) | W2: =IFERROR(LET(mtype,XLOOKUP($D2,'Move Editor'!$B:$B,'Move Editor'!$C:$C,""),cat,XLOOKUP($D2,'Move Editor'!$B:$B,'Move Editor'!$D:$D,""),pow,XLOOKUP($D2,'Move Editor'!$B:$B,'Move Editor'!$E:$E,0),acc,XLOOKUP($D2,'Move Editor'!$B:$B,'Move Editor'!$F:$F,100),atk,IF(cat="Physical",FLOOR((FLOOR(((2*XLOOKUP('Boss Editor'!$C$4,'Pokemon Editor'!$A:$A,'Pokemon Editor'!$F:$F,0)+31+FLOOR('Boss Editor'!$H$4/4))*'Boss Editor'!$D$4)/100)+5)*XLOOKUP('Boss Editor'!$E$4,'Nature Editor'!$A:$A,'Nature Editor'!$B:$B,1)),FLOOR((FLOOR(((2*XLOOKUP('Boss Editor'!$C$4,'Pokemon Editor'!$A:$A,'Pokemon Editor'!$H:$H,0)+31+FLOOR('Boss Editor'!$J$4/4))*'Boss Editor'!$D$4)/100)+5)*XLOOKUP('Boss Editor'!$E$4,'Nature Editor'!$A:$A,'Nature Editor'!$D:$D,1))),def,IF(cat="Physical",FLOOR((FLOOR(((2*XLOOKUP($K2,'Pokemon Editor'!$A:$A,'Pokemon Editor'!$G:$G,0)+31+FLOOR($Q2/4))*$L2)/100)+5)*XLOOKUP($M2,'Nature Editor'!$A:$A,'Nature Editor'!$C:$C,1)),FLOOR((FLOOR(((2*XLOOKUP($K2,'Pokemon Editor'!$A:$A,'Pokemon Editor'!$I:$I,0)+31+FLOOR($S2/4))*$L2)/100)+5)*XLOOKUP($M2,'Nature Editor'!$A:$A,'Nature Editor'!$E:$E,1))),stab,IF(OR(mtype=XLOOKUP('Boss Editor'!$C$4,'Pokemon Editor'!$A:$A,'Pokemon Editor'!$C:$C,""),mtype=XLOOKUP('Boss Editor'!$C$4,'Pokemon Editor'!$A:$A,'Pokemon Editor'!$D:$D,"")),1.5,1),eff,(INDEX('Type Chart'!$B:$S,MATCH(mtype,'Type Chart'!$A:$A,0),MATCH(XLOOKUP($K2,'Pokemon Editor'!$A:$A,'Pokemon Editor'!$C:$C,""),'Type Chart'!$B$1:$S$1,0))*IF(XLOOKUP($K2,'Pokemon Editor'!$A:$A,'Pokemon Editor'!$D:$D,"")="",1,INDEX('Type Chart'!$B:$S,MATCH(mtype,'Type Chart'!$A:$A,0),MATCH(XLOOKUP($K2,'Pokemon Editor'!$A:$A,'Pokemon Editor'!$D:$D,""),'Type Chart'!$B$1:$S$1,0)))),base,IF(OR(cat="Status",pow=0),0,FLOOR(FLOOR(FLOOR((2*'Boss Editor'!$D$4/5+2)*pow*atk/def)/50)+2)),modifier,stab*eff,FLOOR(base*modifier*0.85)),0) | X2: =IFERROR(LET(mtype,XLOOKUP($D2,'Move Editor'!$B:$B,'Move Editor'!$C:$C,""),cat,XLOOKUP($D2,'Move Editor'!$B:$B,'Move Editor'!$D:$D,""),pow,XLOOKUP($D2,'Move Editor'!$B:$B,'Move Editor'!$E:$E,0),acc,XLOOKUP($D2,'Move Editor'!$B:$B,'Move Editor'!$F:$F,100),atk,IF(cat="Physical",FLOOR((FLOOR(((2*XLOOKUP('Boss Editor'!$C$4,'Pokemon Editor'!$A:$A,'Pokemon Editor'!$F:$F,0)+31+FLOOR('Boss Editor'!$H$4/4))*'Boss Editor'!$D$4)/100)+5)*XLOOKUP('Boss Editor'!$E$4,'Nature Editor'!$A:$A,'Nature Editor'!$B:$B,1)),FLOOR((FLOOR(((2*XLOOKUP('Boss Editor'!$C$4,'Pokemon Editor'!$A:$A,'Pokemon Editor'!$H:$H,0)+31+FLOOR('Boss Editor'!$J$4/4))*'Boss Editor'!$D$4)/100)+5)*XLOOKUP('Boss Editor'!$E$4,'Nature Editor'!$A:$A,'Nature Editor'!$D:$D,1))),def,IF(cat="Physical",FLOOR((FLOOR(((2*XLOOKUP($K2,'Pokemon Editor'!$A:$A,'Pokemon Editor'!$G:$G,0)+31+FLOOR($Q2/4))*$L2)/100)+5)*XLOOKUP($M2,'Nature Editor'!$A:$A,'Nature Editor'!$C:$C,1)),FLOOR((FLOOR(((2*XLOOKUP($K2,'Pokemon Editor'!$A:$A,'Pokemon Editor'!$I:$I,0)+31+FLOOR($S2/4))*$L2)/100)+5)*XLOOKUP($M2,'Nature Editor'!$A:$A,'Nature Editor'!$E:$E,1))),stab,IF(OR(mtype=XLOOKUP('Boss Editor'!$C$4,'Pokemon Editor'!$A:$A,'Pokemon Editor'!$C:$C,""),mtype=XLOOKUP('Boss Editor'!$C$4,'Pokemon Editor'!$A:$A,'Pokemon Editor'!$D:$D,"")),1.5,1),eff,(INDEX('Type Chart'!$B:$S,MATCH(mtype,'Type Chart'!$A:$A,0),MATCH(XLOOKUP($K2,'Pokemon Editor'!$A:$A,'Pokemon Editor'!$C:$C,""),'Type Chart'!$B$1:$S$1,0))*IF(XLOOKUP($K2,'Pokemon Editor'!$A:$A,'Pokemon Editor'!$D:$D,"")="",1,INDEX('Type Chart'!$B:$S,MATCH(mtype,'Type Chart'!$A:$A,0),MATCH(XLOOKUP($K2,'Pokemon Editor'!$A:$A,'Pokemon Editor'!$D:$D,""),'Type Chart'!$B$1:$S$1,0)))),base,IF(OR(cat="Status",pow=0),0,FLOOR(FLOOR(FLOOR((2*'Boss Editor'!$D$4/5+2)*pow*atk/def)/50)+2)),modifier,stab*eff,FLOOR(base*modifier)),0) | Y2: SPECIES_PANCHAM
A3: =XLOOKUP(K3,'Pokemon Editor'!$A:$A,'Pokemon Editor'!$B:$B,K3) | B3: =IF($Z3<>"",$Z3,IFERROR(INDEX(FILTER('Move Comparison'!$D$2:$D,'Move Comparison'!$Q$2:$Q=$Y3,'Move Comparison'!$M$2:$M=MAXIFS('Move Comparison'!$M$2:$M,'Move Comparison'!$Q$2:$Q,$Y3),'Move Comparison'!$D$2:$D<>""),1),"")) | C3: =IFERROR(LET(mtype,XLOOKUP($B3,'Move Editor'!$B:$B,'Move Editor'!$C:$C,""),cat,XLOOKUP($B3,'Move Editor'!$B:$B,'Move Editor'!$D:$D,""),pow,XLOOKUP($B3,'Move Editor'!$B:$B,'Move Editor'!$E:$E,0),acc,XLOOKUP($B3,'Move Editor'!$B:$B,'Move Editor'!$F:$F,100),atk,IF(cat="Physical",FLOOR((FLOOR(((2*XLOOKUP($K3,'Pokemon Editor'!$A:$A,'Pokemon Editor'!$F:$F,0)+31+FLOOR($P3/4))*$L3)/100)+5)*XLOOKUP($M3,'Nature Editor'!$A:$A,'Nature Editor'!$B:$B,1)),FLOOR((FLOOR(((2*XLOOKUP($K3,'Pokemon Editor'!$A:$A,'Pokemon Editor'!$H:$H,0)+31+FLOOR($R3/4))*$L3)/100)+5)*XLOOKUP($M3,'Nature Editor'!$A:$A,'Nature Editor'!$D:$D,1))),def,IF(cat="Physical",FLOOR((FLOOR(((2*XLOOKUP('Boss Editor'!$C$4,'Pokemon Editor'!$A:$A,'Pokemon Editor'!$G:$G,0)+31+FLOOR('Boss Editor'!$I$4/4))*'Boss Editor'!$D$4)/100)+5)*XLOOKUP('Boss Editor'!$E$4,'Nature Editor'!$A:$A,'Nature Editor'!$C:$C,1)),FLOOR((FLOOR(((2*XLOOKUP('Boss Editor'!$C$4,'Pokemon Editor'!$A:$A,'Pokemon Editor'!$I:$I,0)+31+FLOOR('Boss Editor'!$K$4/4))*'Boss Editor'!$D$4)/100)+5)*XLOOKUP('Boss Editor'!$E$4,'Nature Editor'!$A:$A,'Nature Editor'!$E:$E,1))),stab,IF(OR(mtype=XLOOKUP($K3,'Pokemon Editor'!$A:$A,'Pokemon Editor'!$C:$C,""),mtype=XLOOKUP($K3,'Pokemon Editor'!$A:$A,'Pokemon Editor'!$D:$D,"")),1.5,1),eff,(INDEX('Type Chart'!$B:$S,MATCH(mtype,'Type Chart'!$A:$A,0),MATCH(XLOOKUP('Boss Editor'!$C$4,'Pokemon Editor'!$A:$A,'Pokemon Editor'!$C:$C,""),'Type Chart'!$B$1:$S$1,0))*IF(XLOOKUP('Boss Editor'!$C$4,'Pokemon Editor'!$A:$A,'Pokemon Editor'!$D:$D,"")="",1,INDEX('Type Chart'!$B:$S,MATCH(mtype,'Type Chart'!$A:$A,0),MATCH(XLOOKUP('Boss Editor'!$C$4,'Pokemon Editor'!$A:$A,'Pokemon Editor'!$D:$D,""),'Type Chart'!$B$1:$S$1,0)))),base,IF(OR(cat="Status",pow=0),0,FLOOR(FLOOR(FLOOR((2*$L3/5+2)*pow*atk/def)/50)+2)),modifier,stab*eff,AVERAGE(ARRAYFORMULA(FLOOR(base*modifier*SEQUENCE(16,1,85,1)/100)))/(FLOOR(((2*XLOOKUP('Boss Editor'!$C$4,'Pokemon Editor'!$A:$A,'Pokemon Editor'!$E:$E,0)+31+FLOOR('Boss Editor'!$G$4/4))*'Boss Editor'!$D$4)/100)+'Boss Editor'!$D$4+10)),0) | D3: Astonish | E3: =IFERROR(LET(mtype,XLOOKUP($D3,'Move Editor'!$B:$B,'Move Editor'!$C:$C,""),cat,XLOOKUP($D3,'Move Editor'!$B:$B,'Move Editor'!$D:$D,""),pow,XLOOKUP($D3,'Move Editor'!$B:$B,'Move Editor'!$E:$E,0),acc,XLOOKUP($D3,'Move Editor'!$B:$B,'Move Editor'!$F:$F,100),atk,IF(cat="Physical",FLOOR((FLOOR(((2*XLOOKUP('Boss Editor'!$C$4,'Pokemon Editor'!$A:$A,'Pokemon Editor'!$F:$F,0)+31+FLOOR('Boss Editor'!$H$4/4))*'Boss Editor'!$D$4)/100)+5)*XLOOKUP('Boss Editor'!$E$4,'Nature Editor'!$A:$A,'Nature Editor'!$B:$B,1)),FLOOR((FLOOR(((2*XLOOKUP('Boss Editor'!$C$4,'Pokemon Editor'!$A:$A,'Pokemon Editor'!$H:$H,0)+31+FLOOR('Boss Editor'!$J$4/4))*'Boss Editor'!$D$4)/100)+5)*XLOOKUP('Boss Editor'!$E$4,'Nature Editor'!$A:$A,'Nature Editor'!$D:$D,1))),def,IF(cat="Physical",FLOOR((FLOOR(((2*XLOOKUP($K3,'Pokemon Editor'!$A:$A,'Pokemon Editor'!$G:$G,0)+31+FLOOR($Q3/4))*$L3)/100)+5)*XLOOKUP($M3,'Nature Editor'!$A:$A,'Nature Editor'!$C:$C,1)),FLOOR((FLOOR(((2*XLOOKUP($K3,'Pokemon Editor'!$A:$A,'Pokemon Editor'!$I:$I,0)+31+FLOOR($S3/4))*$L3)/100)+5)*XLOOKUP($M3,'Nature Editor'!$A:$A,'Nature Editor'!$E:$E,1))),stab,IF(OR(mtype=XLOOKUP('Boss Editor'!$C$4,'Pokemon Editor'!$A:$A,'Pokemon Editor'!$C:$C,""),mtype=XLOOKUP('Boss Editor'!$C$4,'Pokemon Editor'!$A:$A,'Pokemon Editor'!$D:$D,"")),1.5,1),eff,(INDEX('Type Chart'!$B:$S,MATCH(mtype,'Type Chart'!$A:$A,0),MATCH(XLOOKUP($K3,'Pokemon Editor'!$A:$A,'Pokemon Editor'!$C:$C,""),'Type Chart'!$B$1:$S$1,0))*IF(XLOOKUP($K3,'Pokemon Editor'!$A:$A,'Pokemon Editor'!$D:$D,"")="",1,INDEX('Type Chart'!$B:$S,MATCH(mtype,'Type Chart'!$A:$A,0),MATCH(XLOOKUP($K3,'Pokemon Editor'!$A:$A,'Pokemon Editor'!$D:$D,""),'Type Chart'!$B$1:$S$1,0)))),base,IF(OR(cat="Status",pow=0),0,FLOOR(FLOOR(FLOOR((2*'Boss Editor'!$D$4/5+2)*pow*atk/def)/50)+2)),modifier,stab*eff,AVERAGE(ARRAYFORMULA(FLOOR(base*modifier*SEQUENCE(16,1,85,1)/100)))/(FLOOR(((2*XLOOKUP($K3,'Pokemon Editor'!$A:$A,'Pokemon Editor'!$E:$E,0)+31+FLOOR($O3/4))*$L3)/100)+$L3+10)),0) | F3: =FLOOR((FLOOR(((2*XLOOKUP($K3,'Pokemon Editor'!$A:$A,'Pokemon Editor'!$J:$J,0)+31+FLOOR($T3/4))*$L3)/100)+5)*XLOOKUP($M3,'Nature Editor'!$A:$A,'Nature Editor'!$F:$F,1)) | G3: =FLOOR((FLOOR(((2*XLOOKUP('Boss Editor'!$C$4,'Pokemon Editor'!$A:$A,'Pokemon Editor'!$J:$J,0)+31+FLOOR('Boss Editor'!$L$4/4))*'Boss Editor'!$D$4)/100)+5)*XLOOKUP('Boss Editor'!$E$4,'Nature Editor'!$A:$A,'Nature Editor'!$F:$F,1)) | H3: =IF(F3>G3,"Yes","No") | I3: =C3-E3 | J3: =IFS(AND(C3>=0.5,E3<0.5),"Dominant",AND(C3>=0.35,E3<0.75),"Strong",AND(C3>=0.25,E3<1),"Viable",AND(C3>=0.15,E3<1.25),"Risky",TRUE,"Poor") | K3: =REDUCE($Y3,SEQUENCE(2),LAMBDA(current_species,unused_step,IFERROR(INDEX(FILTER('Evolution Editor'!$D$2:$D,'Evolution Editor'!$A$2:$A=current_species,'Evolution Editor'!$F$2:$F=TRUE,'Evolution Editor'!$E$2:$E<=$L3),1),current_species))) | L3: 15 | M3: Neutral | N3: ABILITY_MOLD_BREAKER | O3: 0 | P3: 0 | Q3: 0 | R3: 0 | S3: 0 | T3: 0 | U3: =IFERROR(LET(mtype,XLOOKUP($B3,'Move Editor'!$B:$B,'Move Editor'!$C:$C,""),cat,XLOOKUP($B3,'Move Editor'!$B:$B,'Move Editor'!$D:$D,""),pow,XLOOKUP($B3,'Move Editor'!$B:$B,'Move Editor'!$E:$E,0),acc,XLOOKUP($B3,'Move Editor'!$B:$B,'Move Editor'!$F:$F,100),atk,IF(cat="Physical",FLOOR((FLOOR(((2*XLOOKUP($K3,'Pokemon Editor'!$A:$A,'Pokemon Editor'!$F:$F,0)+31+FLOOR($P3/4))*$L3)/100)+5)*XLOOKUP($M3,'Nature Editor'!$A:$A,'Nature Editor'!$B:$B,1)),FLOOR((FLOOR(((2*XLOOKUP($K3,'Pokemon Editor'!$A:$A,'Pokemon Editor'!$H:$H,0)+31+FLOOR($R3/4))*$L3)/100)+5)*XLOOKUP($M3,'Nature Editor'!$A:$A,'Nature Editor'!$D:$D,1))),def,IF(cat="Physical",FLOOR((FLOOR(((2*XLOOKUP('Boss Editor'!$C$4,'Pokemon Editor'!$A:$A,'Pokemon Editor'!$G:$G,0)+31+FLOOR('Boss Editor'!$I$4/4))*'Boss Editor'!$D$4)/100)+5)*XLOOKUP('Boss Editor'!$E$4,'Nature Editor'!$A:$A,'Nature Editor'!$C:$C,1)),FLOOR((FLOOR(((2*XLOOKUP('Boss Editor'!$C$4,'Pokemon Editor'!$A:$A,'Pokemon Editor'!$I:$I,0)+31+FLOOR('Boss Editor'!$K$4/4))*'Boss Editor'!$D$4)/100)+5)*XLOOKUP('Boss Editor'!$E$4,'Nature Editor'!$A:$A,'Nature Editor'!$E:$E,1))),stab,IF(OR(mtype=XLOOKUP($K3,'Pokemon Editor'!$A:$A,'Pokemon Editor'!$C:$C,""),mtype=XLOOKUP($K3,'Pokemon Editor'!$A:$A,'Pokemon Editor'!$D:$D,"")),1.5,1),eff,(INDEX('Type Chart'!$B:$S,MATCH(mtype,'Type Chart'!$A:$A,0),MATCH(XLOOKUP('Boss Editor'!$C$4,'Pokemon Editor'!$A:$A,'Pokemon Editor'!$C:$C,""),'Type Chart'!$B$1:$S$1,0))*IF(XLOOKUP('Boss Editor'!$C$4,'Pokemon Editor'!$A:$A,'Pokemon Editor'!$D:$D,"")="",1,INDEX('Type Chart'!$B:$S,MATCH(mtype,'Type Chart'!$A:$A,0),MATCH(XLOOKUP('Boss Editor'!$C$4,'Pokemon Editor'!$A:$A,'Pokemon Editor'!$D:$D,""),'Type Chart'!$B$1:$S$1,0)))),base,IF(OR(cat="Status",pow=0),0,FLOOR(FLOOR(FLOOR((2*$L3/5+2)*pow*atk/def)/50)+2)),modifier,stab*eff,FLOOR(base*modifier*0.85)),0) | V3: =IFERROR(LET(mtype,XLOOKUP($B3,'Move Editor'!$B:$B,'Move Editor'!$C:$C,""),cat,XLOOKUP($B3,'Move Editor'!$B:$B,'Move Editor'!$D:$D,""),pow,XLOOKUP($B3,'Move Editor'!$B:$B,'Move Editor'!$E:$E,0),acc,XLOOKUP($B3,'Move Editor'!$B:$B,'Move Editor'!$F:$F,100),atk,IF(cat="Physical",FLOOR((FLOOR(((2*XLOOKUP($K3,'Pokemon Editor'!$A:$A,'Pokemon Editor'!$F:$F,0)+31+FLOOR($P3/4))*$L3)/100)+5)*XLOOKUP($M3,'Nature Editor'!$A:$A,'Nature Editor'!$B:$B,1)),FLOOR((FLOOR(((2*XLOOKUP($K3,'Pokemon Editor'!$A:$A,'Pokemon Editor'!$H:$H,0)+31+FLOOR($R3/4))*$L3)/100)+5)*XLOOKUP($M3,'Nature Editor'!$A:$A,'Nature Editor'!$D:$D,1))),def,IF(cat="Physical",FLOOR((FLOOR(((2*XLOOKUP('Boss Editor'!$C$4,'Pokemon Editor'!$A:$A,'Pokemon Editor'!$G:$G,0)+31+FLOOR('Boss Editor'!$I$4/4))*'Boss Editor'!$D$4)/100)+5)*XLOOKUP('Boss Editor'!$E$4,'Nature Editor'!$A:$A,'Nature Editor'!$C:$C,1)),FLOOR((FLOOR(((2*XLOOKUP('Boss Editor'!$C$4,'Pokemon Editor'!$A:$A,'Pokemon Editor'!$I:$I,0)+31+FLOOR('Boss Editor'!$K$4/4))*'Boss Editor'!$D$4)/100)+5)*XLOOKUP('Boss Editor'!$E$4,'Nature Editor'!$A:$A,'Nature Editor'!$E:$E,1))),stab,IF(OR(mtype=XLOOKUP($K3,'Pokemon Editor'!$A:$A,'Pokemon Editor'!$C:$C,""),mtype=XLOOKUP($K3,'Pokemon Editor'!$A:$A,'Pokemon Editor'!$D:$D,"")),1.5,1),eff,(INDEX('Type Chart'!$B:$S,MATCH(mtype,'Type Chart'!$A:$A,0),MATCH(XLOOKUP('Boss Editor'!$C$4,'Pokemon Editor'!$A:$A,'Pokemon Editor'!$C:$C,""),'Type Chart'!$B$1:$S$1,0))*IF(XLOOKUP('Boss Editor'!$C$4,'Pokemon Editor'!$A:$A,'Pokemon Editor'!$D:$D,"")="",1,INDEX('Type Chart'!$B:$S,MATCH(mtype,'Type Chart'!$A:$A,0),MATCH(XLOOKUP('Boss Editor'!$C$4,'Pokemon Editor'!$A:$A,'Pokemon Editor'!$D:$D,""),'Type Chart'!$B$1:$S$1,0)))),base,IF(OR(cat="Status",pow=0),0,FLOOR(FLOOR(FLOOR((2*$L3/5+2)*pow*atk/def)/50)+2)),modifier,stab*eff,FLOOR(base*modifier)),0) | W3: =IFERROR(LET(mtype,XLOOKUP($D3,'Move Editor'!$B:$B,'Move Editor'!$C:$C,""),cat,XLOOKUP($D3,'Move Editor'!$B:$B,'Move Editor'!$D:$D,""),pow,XLOOKUP($D3,'Move Editor'!$B:$B,'Move Editor'!$E:$E,0),acc,XLOOKUP($D3,'Move Editor'!$B:$B,'Move Editor'!$F:$F,100),atk,IF(cat="Physical",FLOOR((FLOOR(((2*XLOOKUP('Boss Editor'!$C$4,'Pokemon Editor'!$A:$A,'Pokemon Editor'!$F:$F,0)+31+FLOOR('Boss Editor'!$H$4/4))*'Boss Editor'!$D$4)/100)+5)*XLOOKUP('Boss Editor'!$E$4,'Nature Editor'!$A:$A,'Nature Editor'!$B:$B,1)),FLOOR((FLOOR(((2*XLOOKUP('Boss Editor'!$C$4,'Pokemon Editor'!$A:$A,'Pokemon Editor'!$H:$H,0)+31+FLOOR('Boss Editor'!$J$4/4))*'Boss Editor'!$D$4)/100)+5)*XLOOKUP('Boss Editor'!$E$4,'Nature Editor'!$A:$A,'Nature Editor'!$D:$D,1))),def,IF(cat="Physical",FLOOR((FLOOR(((2*XLOOKUP($K3,'Pokemon Editor'!$A:$A,'Pokemon Editor'!$G:$G,0)+31+FLOOR($Q3/4))*$L3)/100)+5)*XLOOKUP($M3,'Nature Editor'!$A:$A,'Nature Editor'!$C:$C,1)),FLOOR((FLOOR(((2*XLOOKUP($K3,'Pokemon Editor'!$A:$A,'Pokemon Editor'!$I:$I,0)+31+FLOOR($S3/4))*$L3)/100)+5)*XLOOKUP($M3,'Nature Editor'!$A:$A,'Nature Editor'!$E:$E,1))),stab,IF(OR(mtype=XLOOKUP('Boss Editor'!$C$4,'Pokemon Editor'!$A:$A,'Pokemon Editor'!$C:$C,""),mtype=XLOOKUP('Boss Editor'!$C$4,'Pokemon Editor'!$A:$A,'Pokemon Editor'!$D:$D,"")),1.5,1),eff,(INDEX('Type Chart'!$B:$S,MATCH(mtype,'Type Chart'!$A:$A,0),MATCH(XLOOKUP($K3,'Pokemon Editor'!$A:$A,'Pokemon Editor'!$C:$C,""),'Type Chart'!$B$1:$S$1,0))*IF(XLOOKUP($K3,'Pokemon Editor'!$A:$A,'Pokemon Editor'!$D:$D,"")="",1,INDEX('Type Chart'!$B:$S,MATCH(mtype,'Type Chart'!$A:$A,0),MATCH(XLOOKUP($K3,'Pokemon Editor'!$A:$A,'Pokemon Editor'!$D:$D,""),'Type Chart'!$B$1:$S$1,0)))),base,IF(OR(cat="Status",pow=0),0,FLOOR(FLOOR(FLOOR((2*'Boss Editor'!$D$4/5+2)*pow*atk/def)/50)+2)),modifier,stab*eff,FLOOR(base*modifier*0.85)),0) | X3: =IFERROR(LET(mtype,XLOOKUP($D3,'Move Editor'!$B:$B,'Move Editor'!$C:$C,""),cat,XLOOKUP($D3,'Move Editor'!$B:$B,'Move Editor'!$D:$D,""),pow,XLOOKUP($D3,'Move Editor'!$B:$B,'Move Editor'!$E:$E,0),acc,XLOOKUP($D3,'Move Editor'!$B:$B,'Move Editor'!$F:$F,100),atk,IF(cat="Physical",FLOOR((FLOOR(((2*XLOOKUP('Boss Editor'!$C$4,'Pokemon Editor'!$A:$A,'Pokemon Editor'!$F:$F,0)+31+FLOOR('Boss Editor'!$H$4/4))*'Boss Editor'!$D$4)/100)+5)*XLOOKUP('Boss Editor'!$E$4,'Nature Editor'!$A:$A,'Nature Editor'!$B:$B,1)),FLOOR((FLOOR(((2*XLOOKUP('Boss Editor'!$C$4,'Pokemon Editor'!$A:$A,'Pokemon Editor'!$H:$H,0)+31+FLOOR('Boss Editor'!$J$4/4))*'Boss Editor'!$D$4)/100)+5)*XLOOKUP('Boss Editor'!$E$4,'Nature Editor'!$A:$A,'Nature Editor'!$D:$D,1))),def,IF(cat="Physical",FLOOR((FLOOR(((2*XLOOKUP($K3,'Pokemon Editor'!$A:$A,'Pokemon Editor'!$G:$G,0)+31+FLOOR($Q3/4))*$L3)/100)+5)*XLOOKUP($M3,'Nature Editor'!$A:$A,'Nature Editor'!$C:$C,1)),FLOOR((FLOOR(((2*XLOOKUP($K3,'Pokemon Editor'!$A:$A,'Pokemon Editor'!$I:$I,0)+31+FLOOR($S3/4))*$L3)/100)+5)*XLOOKUP($M3,'Nature Editor'!$A:$A,'Nature Editor'!$E:$E,1))),stab,IF(OR(mtype=XLOOKUP('Boss Editor'!$C$4,'Pokemon Editor'!$A:$A,'Pokemon Editor'!$C:$C,""),mtype=XLOOKUP('Boss Editor'!$C$4,'Pokemon Editor'!$A:$A,'Pokemon Editor'!$D:$D,"")),1.5,1),eff,(INDEX('Type Chart'!$B:$S,MATCH(mtype,'Type Chart'!$A:$A,0),MATCH(XLOOKUP($K3,'Pokemon Editor'!$A:$A,'Pokemon Editor'!$C:$C,""),'Type Chart'!$B$1:$S$1,0))*IF(XLOOKUP($K3,'Pokemon Editor'!$A:$A,'Pokemon Editor'!$D:$D,"")="",1,INDEX('Type Chart'!$B:$S,MATCH(mtype,'Type Chart'!$A:$A,0),MATCH(XLOOKUP($K3,'Pokemon Editor'!$A:$A,'Pokemon Editor'!$D:$D,""),'Type Chart'!$B$1:$S$1,0)))),base,IF(OR(cat="Status",pow=0),0,FLOOR(FLOOR(FLOOR((2*'Boss Editor'!$D$4/5+2)*pow*atk/def)/50)+2)),modifier,stab*eff,FLOOR(base*modifier)),0) | Y3: SPECIES_TINKATINK
A4: =XLOOKUP(K4,'Pokemon Editor'!$A:$A,'Pokemon Editor'!$B:$B,K4) | B4: =IF($Z4<>"",$Z4,IFERROR(INDEX(FILTER('Move Comparison'!$D$2:$D,'Move Comparison'!$Q$2:$Q=$Y4,'Move Comparison'!$M$2:$M=MAXIFS('Move Comparison'!$M$2:$M,'Move Comparison'!$Q$2:$Q,$Y4),'Move Comparison'!$D$2:$D<>""),1),"")) | C4: =IFERROR(LET(mtype,XLOOKUP($B4,'Move Editor'!$B:$B,'Move Editor'!$C:$C,""),cat,XLOOKUP($B4,'Move Editor'!$B:$B,'Move Editor'!$D:$D,""),pow,XLOOKUP($B4,'Move Editor'!$B:$B,'Move Editor'!$E:$E,0),acc,XLOOKUP($B4,'Move Editor'!$B:$B,'Move Editor'!$F:$F,100),atk,IF(cat="Physical",FLOOR((FLOOR(((2*XLOOKUP($K4,'Pokemon Editor'!$A:$A,'Pokemon Editor'!$F:$F,0)+31+FLOOR($P4/4))*$L4)/100)+5)*XLOOKUP($M4,'Nature Editor'!$A:$A,'Nature Editor'!$B:$B,1)),FLOOR((FLOOR(((2*XLOOKUP($K4,'Pokemon Editor'!$A:$A,'Pokemon Editor'!$H:$H,0)+31+FLOOR($R4/4))*$L4)/100)+5)*XLOOKUP($M4,'Nature Editor'!$A:$A,'Nature Editor'!$D:$D,1))),def,IF(cat="Physical",FLOOR((FLOOR(((2*XLOOKUP('Boss Editor'!$C$4,'Pokemon Editor'!$A:$A,'Pokemon Editor'!$G:$G,0)+31+FLOOR('Boss Editor'!$I$4/4))*'Boss Editor'!$D$4)/100)+5)*XLOOKUP('Boss Editor'!$E$4,'Nature Editor'!$A:$A,'Nature Editor'!$C:$C,1)),FLOOR((FLOOR(((2*XLOOKUP('Boss Editor'!$C$4,'Pokemon Editor'!$A:$A,'Pokemon Editor'!$I:$I,0)+31+FLOOR('Boss Editor'!$K$4/4))*'Boss Editor'!$D$4)/100)+5)*XLOOKUP('Boss Editor'!$E$4,'Nature Editor'!$A:$A,'Nature Editor'!$E:$E,1))),stab,IF(OR(mtype=XLOOKUP($K4,'Pokemon Editor'!$A:$A,'Pokemon Editor'!$C:$C,""),mtype=XLOOKUP($K4,'Pokemon Editor'!$A:$A,'Pokemon Editor'!$D:$D,"")),1.5,1),eff,(INDEX('Type Chart'!$B:$S,MATCH(mtype,'Type Chart'!$A:$A,0),MATCH(XLOOKUP('Boss Editor'!$C$4,'Pokemon Editor'!$A:$A,'Pokemon Editor'!$C:$C,""),'Type Chart'!$B$1:$S$1,0))*IF(XLOOKUP('Boss Editor'!$C$4,'Pokemon Editor'!$A:$A,'Pokemon Editor'!$D:$D,"")="",1,INDEX('Type Chart'!$B:$S,MATCH(mtype,'Type Chart'!$A:$A,0),MATCH(XLOOKUP('Boss Editor'!$C$4,'Pokemon Editor'!$A:$A,'Pokemon Editor'!$D:$D,""),'Type Chart'!$B$1:$S$1,0)))),base,IF(OR(cat="Status",pow=0),0,FLOOR(FLOOR(FLOOR((2*$L4/5+2)*pow*atk/def)/50)+2)),modifier,stab*eff,AVERAGE(ARRAYFORMULA(FLOOR(base*modifier*SEQUENCE(16,1,85,1)/100)))/(FLOOR(((2*XLOOKUP('Boss Editor'!$C$4,'Pokemon Editor'!$A:$A,'Pokemon Editor'!$E:$E,0)+31+FLOOR('Boss Editor'!$G$4/4))*'Boss Editor'!$D$4)/100)+'Boss Editor'!$D$4+10)),0) | D4: Acid | E4: =IFERROR(LET(mtype,XLOOKUP($D4,'Move Editor'!$B:$B,'Move Editor'!$C:$C,""),cat,XLOOKUP($D4,'Move Editor'!$B:$B,'Move Editor'!$D:$D,""),pow,XLOOKUP($D4,'Move Editor'!$B:$B,'Move Editor'!$E:$E,0),acc,XLOOKUP($D4,'Move Editor'!$B:$B,'Move Editor'!$F:$F,100),atk,IF(cat="Physical",FLOOR((FLOOR(((2*XLOOKUP('Boss Editor'!$C$4,'Pokemon Editor'!$A:$A,'Pokemon Editor'!$F:$F,0)+31+FLOOR('Boss Editor'!$H$4/4))*'Boss Editor'!$D$4)/100)+5)*XLOOKUP('Boss Editor'!$E$4,'Nature Editor'!$A:$A,'Nature Editor'!$B:$B,1)),FLOOR((FLOOR(((2*XLOOKUP('Boss Editor'!$C$4,'Pokemon Editor'!$A:$A,'Pokemon Editor'!$H:$H,0)+31+FLOOR('Boss Editor'!$J$4/4))*'Boss Editor'!$D$4)/100)+5)*XLOOKUP('Boss Editor'!$E$4,'Nature Editor'!$A:$A,'Nature Editor'!$D:$D,1))),def,IF(cat="Physical",FLOOR((FLOOR(((2*XLOOKUP($K4,'Pokemon Editor'!$A:$A,'Pokemon Editor'!$G:$G,0)+31+FLOOR($Q4/4))*$L4)/100)+5)*XLOOKUP($M4,'Nature Editor'!$A:$A,'Nature Editor'!$C:$C,1)),FLOOR((FLOOR(((2*XLOOKUP($K4,'Pokemon Editor'!$A:$A,'Pokemon Editor'!$I:$I,0)+31+FLOOR($S4/4))*$L4)/100)+5)*XLOOKUP($M4,'Nature Editor'!$A:$A,'Nature Editor'!$E:$E,1))),stab,IF(OR(mtype=XLOOKUP('Boss Editor'!$C$4,'Pokemon Editor'!$A:$A,'Pokemon Editor'!$C:$C,""),mtype=XLOOKUP('Boss Editor'!$C$4,'Pokemon Editor'!$A:$A,'Pokemon Editor'!$D:$D,"")),1.5,1),eff,(INDEX('Type Chart'!$B:$S,MATCH(mtype,'Type Chart'!$A:$A,0),MATCH(XLOOKUP($K4,'Pokemon Editor'!$A:$A,'Pokemon Editor'!$C:$C,""),'Type Chart'!$B$1:$S$1,0))*IF(XLOOKUP($K4,'Pokemon Editor'!$A:$A,'Pokemon Editor'!$D:$D,"")="",1,INDEX('Type Chart'!$B:$S,MATCH(mtype,'Type Chart'!$A:$A,0),MATCH(XLOOKUP($K4,'Pokemon Editor'!$A:$A,'Pokemon Editor'!$D:$D,""),'Type Chart'!$B$1:$S$1,0)))),base,IF(OR(cat="Status",pow=0),0,FLOOR(FLOOR(FLOOR((2*'Boss Editor'!$D$4/5+2)*pow*atk/def)/50)+2)),modifier,stab*eff,AVERAGE(ARRAYFORMULA(FLOOR(base*modifier*SEQUENCE(16,1,85,1)/100)))/(FLOOR(((2*XLOOKUP($K4,'Pokemon Editor'!$A:$A,'Pokemon Editor'!$E:$E,0)+31+FLOOR($O4/4))*$L4)/100)+$L4+10)),0) | F4: =FLOOR((FLOOR(((2*XLOOKUP($K4,'Pokemon Editor'!$A:$A,'Pokemon Editor'!$J:$J,0)+31+FLOOR($T4/4))*$L4)/100)+5)*XLOOKUP($M4,'Nature Editor'!$A:$A,'Nature Editor'!$F:$F,1)) | G4: =FLOOR((FLOOR(((2*XLOOKUP('Boss Editor'!$C$4,'Pokemon Editor'!$A:$A,'Pokemon Editor'!$J:$J,0)+31+FLOOR('Boss Editor'!$L$4/4))*'Boss Editor'!$D$4)/100)+5)*XLOOKUP('Boss Editor'!$E$4,'Nature Editor'!$A:$A,'Nature Editor'!$F:$F,1)) | H4: =IF(F4>G4,"Yes","No") | I4: =C4-E4 | J4: =IFS(AND(C4>=0.5,E4<0.5),"Dominant",AND(C4>=0.35,E4<0.75),"Strong",AND(C4>=0.25,E4<1),"Viable",AND(C4>=0.15,E4<1.25),"Risky",TRUE,"Poor") | K4: =REDUCE($Y4,SEQUENCE(2),LAMBDA(current_species,unused_step,IFERROR(INDEX(FILTER('Evolution Editor'!$D$2:$D,'Evolution Editor'!$A$2:$A=current_species,'Evolution Editor'!$F$2:$F=TRUE,'Evolution Editor'!$E$2:$E<=$L4),1),current_species))) | L4: 15 | M4: Neutral | N4: ABILITY_HONEY_GATHER | O4: 0 | P4: 0 | Q4: 0 | R4: 0 | S4: 0 | T4: 0 | U4: =IFERROR(LET(mtype,XLOOKUP($B4,'Move Editor'!$B:$B,'Move Editor'!$C:$C,""),cat,XLOOKUP($B4,'Move Editor'!$B:$B,'Move Editor'!$D:$D,""),pow,XLOOKUP($B4,'Move Editor'!$B:$B,'Move Editor'!$E:$E,0),acc,XLOOKUP($B4,'Move Editor'!$B:$B,'Move Editor'!$F:$F,100),atk,IF(cat="Physical",FLOOR((FLOOR(((2*XLOOKUP($K4,'Pokemon Editor'!$A:$A,'Pokemon Editor'!$F:$F,0)+31+FLOOR($P4/4))*$L4)/100)+5)*XLOOKUP($M4,'Nature Editor'!$A:$A,'Nature Editor'!$B:$B,1)),FLOOR((FLOOR(((2*XLOOKUP($K4,'Pokemon Editor'!$A:$A,'Pokemon Editor'!$H:$H,0)+31+FLOOR($R4/4))*$L4)/100)+5)*XLOOKUP($M4,'Nature Editor'!$A:$A,'Nature Editor'!$D:$D,1))),def,IF(cat="Physical",FLOOR((FLOOR(((2*XLOOKUP('Boss Editor'!$C$4,'Pokemon Editor'!$A:$A,'Pokemon Editor'!$G:$G,0)+31+FLOOR('Boss Editor'!$I$4/4))*'Boss Editor'!$D$4)/100)+5)*XLOOKUP('Boss Editor'!$E$4,'Nature Editor'!$A:$A,'Nature Editor'!$C:$C,1)),FLOOR((FLOOR(((2*XLOOKUP('Boss Editor'!$C$4,'Pokemon Editor'!$A:$A,'Pokemon Editor'!$I:$I,0)+31+FLOOR('Boss Editor'!$K$4/4))*'Boss Editor'!$D$4)/100)+5)*XLOOKUP('Boss Editor'!$E$4,'Nature Editor'!$A:$A,'Nature Editor'!$E:$E,1))),stab,IF(OR(mtype=XLOOKUP($K4,'Pokemon Editor'!$A:$A,'Pokemon Editor'!$C:$C,""),mtype=XLOOKUP($K4,'Pokemon Editor'!$A:$A,'Pokemon Editor'!$D:$D,"")),1.5,1),eff,(INDEX('Type Chart'!$B:$S,MATCH(mtype,'Type Chart'!$A:$A,0),MATCH(XLOOKUP('Boss Editor'!$C$4,'Pokemon Editor'!$A:$A,'Pokemon Editor'!$C:$C,""),'Type Chart'!$B$1:$S$1,0))*IF(XLOOKUP('Boss Editor'!$C$4,'Pokemon Editor'!$A:$A,'Pokemon Editor'!$D:$D,"")="",1,INDEX('Type Chart'!$B:$S,MATCH(mtype,'Type Chart'!$A:$A,0),MATCH(XLOOKUP('Boss Editor'!$C$4,'Pokemon Editor'!$A:$A,'Pokemon Editor'!$D:$D,""),'Type Chart'!$B$1:$S$1,0)))),base,IF(OR(cat="Status",pow=0),0,FLOOR(FLOOR(FLOOR((2*$L4/5+2)*pow*atk/def)/50)+2)),modifier,stab*eff,FLOOR(base*modifier*0.85)),0) | V4: =IFERROR(LET(mtype,XLOOKUP($B4,'Move Editor'!$B:$B,'Move Editor'!$C:$C,""),cat,XLOOKUP($B4,'Move Editor'!$B:$B,'Move Editor'!$D:$D,""),pow,XLOOKUP($B4,'Move Editor'!$B:$B,'Move Editor'!$E:$E,0),acc,XLOOKUP($B4,'Move Editor'!$B:$B,'Move Editor'!$F:$F,100),atk,IF(cat="Physical",FLOOR((FLOOR(((2*XLOOKUP($K4,'Pokemon Editor'!$A:$A,'Pokemon Editor'!$F:$F,0)+31+FLOOR($P4/4))*$L4)/100)+5)*XLOOKUP($M4,'Nature Editor'!$A:$A,'Nature Editor'!$B:$B,1)),FLOOR((FLOOR(((2*XLOOKUP($K4,'Pokemon Editor'!$A:$A,'Pokemon Editor'!$H:$H,0)+31+FLOOR($R4/4))*$L4)/100)+5)*XLOOKUP($M4,'Nature Editor'!$A:$A,'Nature Editor'!$D:$D,1))),def,IF(cat="Physical",FLOOR((FLOOR(((2*XLOOKUP('Boss Editor'!$C$4,'Pokemon Editor'!$A:$A,'Pokemon Editor'!$G:$G,0)+31+FLOOR('Boss Editor'!$I$4/4))*'Boss Editor'!$D$4)/100)+5)*XLOOKUP('Boss Editor'!$E$4,'Nature Editor'!$A:$A,'Nature Editor'!$C:$C,1)),FLOOR((FLOOR(((2*XLOOKUP('Boss Editor'!$C$4,'Pokemon Editor'!$A:$A,'Pokemon Editor'!$I:$I,0)+31+FLOOR('Boss Editor'!$K$4/4))*'Boss Editor'!$D$4)/100)+5)*XLOOKUP('Boss Editor'!$E$4,'Nature Editor'!$A:$A,'Nature Editor'!$E:$E,1))),stab,IF(OR(mtype=XLOOKUP($K4,'Pokemon Editor'!$A:$A,'Pokemon Editor'!$C:$C,""),mtype=XLOOKUP($K4,'Pokemon Editor'!$A:$A,'Pokemon Editor'!$D:$D,"")),1.5,1),eff,(INDEX('Type Chart'!$B:$S,MATCH(mtype,'Type Chart'!$A:$A,0),MATCH(XLOOKUP('Boss Editor'!$C$4,'Pokemon Editor'!$A:$A,'Pokemon Editor'!$C:$C,""),'Type Chart'!$B$1:$S$1,0))*IF(XLOOKUP('Boss Editor'!$C$4,'Pokemon Editor'!$A:$A,'Pokemon Editor'!$D:$D,"")="",1,INDEX('Type Chart'!$B:$S,MATCH(mtype,'Type Chart'!$A:$A,0),MATCH(XLOOKUP('Boss Editor'!$C$4,'Pokemon Editor'!$A:$A,'Pokemon Editor'!$D:$D,""),'Type Chart'!$B$1:$S$1,0)))),base,IF(OR(cat="Status",pow=0),0,FLOOR(FLOOR(FLOOR((2*$L4/5+2)*pow*atk/def)/50)+2)),modifier,stab*eff,FLOOR(base*modifier)),0) | W4: =IFERROR(LET(mtype,XLOOKUP($D4,'Move Editor'!$B:$B,'Move Editor'!$C:$C,""),cat,XLOOKUP($D4,'Move Editor'!$B:$B,'Move Editor'!$D:$D,""),pow,XLOOKUP($D4,'Move Editor'!$B:$B,'Move Editor'!$E:$E,0),acc,XLOOKUP($D4,'Move Editor'!$B:$B,'Move Editor'!$F:$F,100),atk,IF(cat="Physical",FLOOR((FLOOR(((2*XLOOKUP('Boss Editor'!$C$4,'Pokemon Editor'!$A:$A,'Pokemon Editor'!$F:$F,0)+31+FLOOR('Boss Editor'!$H$4/4))*'Boss Editor'!$D$4)/100)+5)*XLOOKUP('Boss Editor'!$E$4,'Nature Editor'!$A:$A,'Nature Editor'!$B:$B,1)),FLOOR((FLOOR(((2*XLOOKUP('Boss Editor'!$C$4,'Pokemon Editor'!$A:$A,'Pokemon Editor'!$H:$H,0)+31+FLOOR('Boss Editor'!$J$4/4))*'Boss Editor'!$D$4)/100)+5)*XLOOKUP('Boss Editor'!$E$4,'Nature Editor'!$A:$A,'Nature Editor'!$D:$D,1))),def,IF(cat="Physical",FLOOR((FLOOR(((2*XLOOKUP($K4,'Pokemon Editor'!$A:$A,'Pokemon Editor'!$G:$G,0)+31+FLOOR($Q4/4))*$L4)/100)+5)*XLOOKUP($M4,'Nature Editor'!$A:$A,'Nature Editor'!$C:$C,1)),FLOOR((FLOOR(((2*XLOOKUP($K4,'Pokemon Editor'!$A:$A,'Pokemon Editor'!$I:$I,0)+31+FLOOR($S4/4))*$L4)/100)+5)*XLOOKUP($M4,'Nature Editor'!$A:$A,'Nature Editor'!$E:$E,1))),stab,IF(OR(mtype=XLOOKUP('Boss Editor'!$C$4,'Pokemon Editor'!$A:$A,'Pokemon Editor'!$C:$C,""),mtype=XLOOKUP('Boss Editor'!$C$4,'Pokemon Editor'!$A:$A,'Pokemon Editor'!$D:$D,"")),1.5,1),eff,(INDEX('Type Chart'!$B:$S,MATCH(mtype,'Type Chart'!$A:$A,0),MATCH(XLOOKUP($K4,'Pokemon Editor'!$A:$A,'Pokemon Editor'!$C:$C,""),'Type Chart'!$B$1:$S$1,0))*IF(XLOOKUP($K4,'Pokemon Editor'!$A:$A,'Pokemon Editor'!$D:$D,"")="",1,INDEX('Type Chart'!$B:$S,MATCH(mtype,'Type Chart'!$A:$A,0),MATCH(XLOOKUP($K4,'Pokemon Editor'!$A:$A,'Pokemon Editor'!$D:$D,""),'Type Chart'!$B$1:$S$1,0)))),base,IF(OR(cat="Status",pow=0),0,FLOOR(FLOOR(FLOOR((2*'Boss Editor'!$D$4/5+2)*pow*atk/def)/50)+2)),modifier,stab*eff,FLOOR(base*modifier*0.85)),0) | X4: =IFERROR(LET(mtype,XLOOKUP($D4,'Move Editor'!$B:$B,'Move Editor'!$C:$C,""),cat,XLOOKUP($D4,'Move Editor'!$B:$B,'Move Editor'!$D:$D,""),pow,XLOOKUP($D4,'Move Editor'!$B:$B,'Move Editor'!$E:$E,0),acc,XLOOKUP($D4,'Move Editor'!$B:$B,'Move Editor'!$F:$F,100),atk,IF(cat="Physical",FLOOR((FLOOR(((2*XLOOKUP('Boss Editor'!$C$4,'Pokemon Editor'!$A:$A,'Pokemon Editor'!$F:$F,0)+31+FLOOR('Boss Editor'!$H$4/4))*'Boss Editor'!$D$4)/100)+5)*XLOOKUP('Boss Editor'!$E$4,'Nature Editor'!$A:$A,'Nature Editor'!$B:$B,1)),FLOOR((FLOOR(((2*XLOOKUP('Boss Editor'!$C$4,'Pokemon Editor'!$A:$A,'Pokemon Editor'!$H:$H,0)+31+FLOOR('Boss Editor'!$J$4/4))*'Boss Editor'!$D$4)/100)+5)*XLOOKUP('Boss Editor'!$E$4,'Nature Editor'!$A:$A,'Nature Editor'!$D:$D,1))),def,IF(cat="Physical",FLOOR((FLOOR(((2*XLOOKUP($K4,'Pokemon Editor'!$A:$A,'Pokemon Editor'!$G:$G,0)+31+FLOOR($Q4/4))*$L4)/100)+5)*XLOOKUP($M4,'Nature Editor'!$A:$A,'Nature Editor'!$C:$C,1)),FLOOR((FLOOR(((2*XLOOKUP($K4,'Pokemon Editor'!$A:$A,'Pokemon Editor'!$I:$I,0)+31+FLOOR($S4/4))*$L4)/100)+5)*XLOOKUP($M4,'Nature Editor'!$A:$A,'Nature Editor'!$E:$E,1))),stab,IF(OR(mtype=XLOOKUP('Boss Editor'!$C$4,'Pokemon Editor'!$A:$A,'Pokemon Editor'!$C:$C,""),mtype=XLOOKUP('Boss Editor'!$C$4,'Pokemon Editor'!$A:$A,'Pokemon Editor'!$D:$D,"")),1.5,1),eff,(INDEX('Type Chart'!$B:$S,MATCH(mtype,'Type Chart'!$A:$A,0),MATCH(XLOOKUP($K4,'Pokemon Editor'!$A:$A,'Pokemon Editor'!$C:$C,""),'Type Chart'!$B$1:$S$1,0))*IF(XLOOKUP($K4,'Pokemon Editor'!$A:$A,'Pokemon Editor'!$D:$D,"")="",1,INDEX('Type Chart'!$B:$S,MATCH(mtype,'Type Chart'!$A:$A,0),MATCH(XLOOKUP($K4,'Pokemon Editor'!$A:$A,'Pokemon Editor'!$D:$D,""),'Type Chart'!$B$1:$S$1,0)))),base,IF(OR(cat="Status",pow=0),0,FLOOR(FLOOR(FLOOR((2*'Boss Editor'!$D$4/5+2)*pow*atk/def)/50)+2)),modifier,stab*eff,FLOOR(base*modifier)),0) | Y4: SPECIES_COMBEE
A5: =XLOOKUP(K5,'Pokemon Editor'!$A:$A,'Pokemon Editor'!$B:$B,K5) | B5: =IF($Z5<>"",$Z5,IFERROR(INDEX(FILTER('Move Comparison'!$D$2:$D,'Move Comparison'!$Q$2:$Q=$Y5,'Move Comparison'!$M$2:$M=MAXIFS('Move Comparison'!$M$2:$M,'Move Comparison'!$Q$2:$Q,$Y5),'Move Comparison'!$D$2:$D<>""),1),"")) | C5: =IFERROR(LET(mtype,XLOOKUP($B5,'Move Editor'!$B:$B,'Move Editor'!$C:$C,""),cat,XLOOKUP($B5,'Move Editor'!$B:$B,'Move Editor'!$D:$D,""),pow,XLOOKUP($B5,'Move Editor'!$B:$B,'Move Editor'!$E:$E,0),acc,XLOOKUP($B5,'Move Editor'!$B:$B,'Move Editor'!$F:$F,100),atk,IF(cat="Physical",FLOOR((FLOOR(((2*XLOOKUP($K5,'Pokemon Editor'!$A:$A,'Pokemon Editor'!$F:$F,0)+31+FLOOR($P5/4))*$L5)/100)+5)*XLOOKUP($M5,'Nature Editor'!$A:$A,'Nature Editor'!$B:$B,1)),FLOOR((FLOOR(((2*XLOOKUP($K5,'Pokemon Editor'!$A:$A,'Pokemon Editor'!$H:$H,0)+31+FLOOR($R5/4))*$L5)/100)+5)*XLOOKUP($M5,'Nature Editor'!$A:$A,'Nature Editor'!$D:$D,1))),def,IF(cat="Physical",FLOOR((FLOOR(((2*XLOOKUP('Boss Editor'!$C$4,'Pokemon Editor'!$A:$A,'Pokemon Editor'!$G:$G,0)+31+FLOOR('Boss Editor'!$I$4/4))*'Boss Editor'!$D$4)/100)+5)*XLOOKUP('Boss Editor'!$E$4,'Nature Editor'!$A:$A,'Nature Editor'!$C:$C,1)),FLOOR((FLOOR(((2*XLOOKUP('Boss Editor'!$C$4,'Pokemon Editor'!$A:$A,'Pokemon Editor'!$I:$I,0)+31+FLOOR('Boss Editor'!$K$4/4))*'Boss Editor'!$D$4)/100)+5)*XLOOKUP('Boss Editor'!$E$4,'Nature Editor'!$A:$A,'Nature Editor'!$E:$E,1))),stab,IF(OR(mtype=XLOOKUP($K5,'Pokemon Editor'!$A:$A,'Pokemon Editor'!$C:$C,""),mtype=XLOOKUP($K5,'Pokemon Editor'!$A:$A,'Pokemon Editor'!$D:$D,"")),1.5,1),eff,(INDEX('Type Chart'!$B:$S,MATCH(mtype,'Type Chart'!$A:$A,0),MATCH(XLOOKUP('Boss Editor'!$C$4,'Pokemon Editor'!$A:$A,'Pokemon Editor'!$C:$C,""),'Type Chart'!$B$1:$S$1,0))*IF(XLOOKUP('Boss Editor'!$C$4,'Pokemon Editor'!$A:$A,'Pokemon Editor'!$D:$D,"")="",1,INDEX('Type Chart'!$B:$S,MATCH(mtype,'Type Chart'!$A:$A,0),MATCH(XLOOKUP('Boss Editor'!$C$4,'Pokemon Editor'!$A:$A,'Pokemon Editor'!$D:$D,""),'Type Chart'!$B$1:$S$1,0)))),base,IF(OR(cat="Status",pow=0),0,FLOOR(FLOOR(FLOOR((2*$L5/5+2)*pow*atk/def)/50)+2)),modifier,stab*eff,AVERAGE(ARRAYFORMULA(FLOOR(base*modifier*SEQUENCE(16,1,85,1)/100)))/(FLOOR(((2*XLOOKUP('Boss Editor'!$C$4,'Pokemon Editor'!$A:$A,'Pokemon Editor'!$E:$E,0)+31+FLOOR('Boss Editor'!$G$4/4))*'Boss Editor'!$D$4)/100)+'Boss Editor'!$D$4+10)),0) | D5: Acid | E5: =IFERROR(LET(mtype,XLOOKUP($D5,'Move Editor'!$B:$B,'Move Editor'!$C:$C,""),cat,XLOOKUP($D5,'Move Editor'!$B:$B,'Move Editor'!$D:$D,""),pow,XLOOKUP($D5,'Move Editor'!$B:$B,'Move Editor'!$E:$E,0),acc,XLOOKUP($D5,'Move Editor'!$B:$B,'Move Editor'!$F:$F,100),atk,IF(cat="Physical",FLOOR((FLOOR(((2*XLOOKUP('Boss Editor'!$C$4,'Pokemon Editor'!$A:$A,'Pokemon Editor'!$F:$F,0)+31+FLOOR('Boss Editor'!$H$4/4))*'Boss Editor'!$D$4)/100)+5)*XLOOKUP('Boss Editor'!$E$4,'Nature Editor'!$A:$A,'Nature Editor'!$B:$B,1)),FLOOR((FLOOR(((2*XLOOKUP('Boss Editor'!$C$4,'Pokemon Editor'!$A:$A,'Pokemon Editor'!$H:$H,0)+31+FLOOR('Boss Editor'!$J$4/4))*'Boss Editor'!$D$4)/100)+5)*XLOOKUP('Boss Editor'!$E$4,'Nature Editor'!$A:$A,'Nature Editor'!$D:$D,1))),def,IF(cat="Physical",FLOOR((FLOOR(((2*XLOOKUP($K5,'Pokemon Editor'!$A:$A,'Pokemon Editor'!$G:$G,0)+31+FLOOR($Q5/4))*$L5)/100)+5)*XLOOKUP($M5,'Nature Editor'!$A:$A,'Nature Editor'!$C:$C,1)),FLOOR((FLOOR(((2*XLOOKUP($K5,'Pokemon Editor'!$A:$A,'Pokemon Editor'!$I:$I,0)+31+FLOOR($S5/4))*$L5)/100)+5)*XLOOKUP($M5,'Nature Editor'!$A:$A,'Nature Editor'!$E:$E,1))),stab,IF(OR(mtype=XLOOKUP('Boss Editor'!$C$4,'Pokemon Editor'!$A:$A,'Pokemon Editor'!$C:$C,""),mtype=XLOOKUP('Boss Editor'!$C$4,'Pokemon Editor'!$A:$A,'Pokemon Editor'!$D:$D,"")),1.5,1),eff,(INDEX('Type Chart'!$B:$S,MATCH(mtype,'Type Chart'!$A:$A,0),MATCH(XLOOKUP($K5,'Pokemon Editor'!$A:$A,'Pokemon Editor'!$C:$C,""),'Type Chart'!$B$1:$S$1,0))*IF(XLOOKUP($K5,'Pokemon Editor'!$A:$A,'Pokemon Editor'!$D:$D,"")="",1,INDEX('Type Chart'!$B:$S,MATCH(mtype,'Type Chart'!$A:$A,0),MATCH(XLOOKUP($K5,'Pokemon Editor'!$A:$A,'Pokemon Editor'!$D:$D,""),'Type Chart'!$B$1:$S$1,0)))),base,IF(OR(cat="Status",pow=0),0,FLOOR(FLOOR(FLOOR((2*'Boss Editor'!$D$4/5+2)*pow*atk/def)/50)+2)),modifier,stab*eff,AVERAGE(ARRAYFORMULA(FLOOR(base*modifier*SEQUENCE(16,1,85,1)/100)))/(FLOOR(((2*XLOOKUP($K5,'Pokemon Editor'!$A:$A,'Pokemon Editor'!$E:$E,0)+31+FLOOR($O5/4))*$L5)/100)+$L5+10)),0) | F5: =FLOOR((FLOOR(((2*XLOOKUP($K5,'Pokemon Editor'!$A:$A,'Pokemon Editor'!$J:$J,0)+31+FLOOR($T5/4))*$L5)/100)+5)*XLOOKUP($M5,'Nature Editor'!$A:$A,'Nature Editor'!$F:$F,1)) | G5: =FLOOR((FLOOR(((2*XLOOKUP('Boss Editor'!$C$4,'Pokemon Editor'!$A:$A,'Pokemon Editor'!$J:$J,0)+31+FLOOR('Boss Editor'!$L$4/4))*'Boss Editor'!$D$4)/100)+5)*XLOOKUP('Boss Editor'!$E$4,'Nature Editor'!$A:$A,'Nature Editor'!$F:$F,1)) | H5: =IF(F5>G5,"Yes","No") | I5: =C5-E5 | J5: =IFS(AND(C5>=0.5,E5<0.5),"Dominant",AND(C5>=0.35,E5<0.75),"Strong",AND(C5>=0.25,E5<1),"Viable",AND(C5>=0.15,E5<1.25),"Risky",TRUE,"Poor") | K5: =REDUCE($Y5,SEQUENCE(2),LAMBDA(current_species,unused_step,IFERROR(INDEX(FILTER('Evolution Editor'!$D$2:$D,'Evolution Editor'!$A$2:$A=current_species,'Evolution Editor'!$F$2:$F=TRUE,'Evolution Editor'!$E$2:$E<=$L5),1),current_species))) | L5: 15 | M5: Neutral | N5: ABILITY_SWARM | O5: 0 | P5: 0 | Q5: 0 | R5: 0 | S5: 0 | T5: 0 | U5: =IFERROR(LET(mtype,XLOOKUP($B5,'Move Editor'!$B:$B,'Move Editor'!$C:$C,""),cat,XLOOKUP($B5,'Move Editor'!$B:$B,'Move Editor'!$D:$D,""),pow,XLOOKUP($B5,'Move Editor'!$B:$B,'Move Editor'!$E:$E,0),acc,XLOOKUP($B5,'Move Editor'!$B:$B,'Move Editor'!$F:$F,100),atk,IF(cat="Physical",FLOOR((FLOOR(((2*XLOOKUP($K5,'Pokemon Editor'!$A:$A,'Pokemon Editor'!$F:$F,0)+31+FLOOR($P5/4))*$L5)/100)+5)*XLOOKUP($M5,'Nature Editor'!$A:$A,'Nature Editor'!$B:$B,1)),FLOOR((FLOOR(((2*XLOOKUP($K5,'Pokemon Editor'!$A:$A,'Pokemon Editor'!$H:$H,0)+31+FLOOR($R5/4))*$L5)/100)+5)*XLOOKUP($M5,'Nature Editor'!$A:$A,'Nature Editor'!$D:$D,1))),def,IF(cat="Physical",FLOOR((FLOOR(((2*XLOOKUP('Boss Editor'!$C$4,'Pokemon Editor'!$A:$A,'Pokemon Editor'!$G:$G,0)+31+FLOOR('Boss Editor'!$I$4/4))*'Boss Editor'!$D$4)/100)+5)*XLOOKUP('Boss Editor'!$E$4,'Nature Editor'!$A:$A,'Nature Editor'!$C:$C,1)),FLOOR((FLOOR(((2*XLOOKUP('Boss Editor'!$C$4,'Pokemon Editor'!$A:$A,'Pokemon Editor'!$I:$I,0)+31+FLOOR('Boss Editor'!$K$4/4))*'Boss Editor'!$D$4)/100)+5)*XLOOKUP('Boss Editor'!$E$4,'Nature Editor'!$A:$A,'Nature Editor'!$E:$E,1))),stab,IF(OR(mtype=XLOOKUP($K5,'Pokemon Editor'!$A:$A,'Pokemon Editor'!$C:$C,""),mtype=XLOOKUP($K5,'Pokemon Editor'!$A:$A,'Pokemon Editor'!$D:$D,"")),1.5,1),eff,(INDEX('Type Chart'!$B:$S,MATCH(mtype,'Type Chart'!$A:$A,0),MATCH(XLOOKUP('Boss Editor'!$C$4,'Pokemon Editor'!$A:$A,'Pokemon Editor'!$C:$C,""),'Type Chart'!$B$1:$S$1,0))*IF(XLOOKUP('Boss Editor'!$C$4,'Pokemon Editor'!$A:$A,'Pokemon Editor'!$D:$D,"")="",1,INDEX('Type Chart'!$B:$S,MATCH(mtype,'Type Chart'!$A:$A,0),MATCH(XLOOKUP('Boss Editor'!$C$4,'Pokemon Editor'!$A:$A,'Pokemon Editor'!$D:$D,""),'Type Chart'!$B$1:$S$1,0)))),base,IF(OR(cat="Status",pow=0),0,FLOOR(FLOOR(FLOOR((2*$L5/5+2)*pow*atk/def)/50)+2)),modifier,stab*eff,FLOOR(base*modifier*0.85)),0) | V5: =IFERROR(LET(mtype,XLOOKUP($B5,'Move Editor'!$B:$B,'Move Editor'!$C:$C,""),cat,XLOOKUP($B5,'Move Editor'!$B:$B,'Move Editor'!$D:$D,""),pow,XLOOKUP($B5,'Move Editor'!$B:$B,'Move Editor'!$E:$E,0),acc,XLOOKUP($B5,'Move Editor'!$B:$B,'Move Editor'!$F:$F,100),atk,IF(cat="Physical",FLOOR((FLOOR(((2*XLOOKUP($K5,'Pokemon Editor'!$A:$A,'Pokemon Editor'!$F:$F,0)+31+FLOOR($P5/4))*$L5)/100)+5)*XLOOKUP($M5,'Nature Editor'!$A:$A,'Nature Editor'!$B:$B,1)),FLOOR((FLOOR(((2*XLOOKUP($K5,'Pokemon Editor'!$A:$A,'Pokemon Editor'!$H:$H,0)+31+FLOOR($R5/4))*$L5)/100)+5)*XLOOKUP($M5,'Nature Editor'!$A:$A,'Nature Editor'!$D:$D,1))),def,IF(cat="Physical",FLOOR((FLOOR(((2*XLOOKUP('Boss Editor'!$C$4,'Pokemon Editor'!$A:$A,'Pokemon Editor'!$G:$G,0)+31+FLOOR('Boss Editor'!$I$4/4))*'Boss Editor'!$D$4)/100)+5)*XLOOKUP('Boss Editor'!$E$4,'Nature Editor'!$A:$A,'Nature Editor'!$C:$C,1)),FLOOR((FLOOR(((2*XLOOKUP('Boss Editor'!$C$4,'Pokemon Editor'!$A:$A,'Pokemon Editor'!$I:$I,0)+31+FLOOR('Boss Editor'!$K$4/4))*'Boss Editor'!$D$4)/100)+5)*XLOOKUP('Boss Editor'!$E$4,'Nature Editor'!$A:$A,'Nature Editor'!$E:$E,1))),stab,IF(OR(mtype=XLOOKUP($K5,'Pokemon Editor'!$A:$A,'Pokemon Editor'!$C:$C,""),mtype=XLOOKUP($K5,'Pokemon Editor'!$A:$A,'Pokemon Editor'!$D:$D,"")),1.5,1),eff,(INDEX('Type Chart'!$B:$S,MATCH(mtype,'Type Chart'!$A:$A,0),MATCH(XLOOKUP('Boss Editor'!$C$4,'Pokemon Editor'!$A:$A,'Pokemon Editor'!$C:$C,""),'Type Chart'!$B$1:$S$1,0))*IF(XLOOKUP('Boss Editor'!$C$4,'Pokemon Editor'!$A:$A,'Pokemon Editor'!$D:$D,"")="",1,INDEX('Type Chart'!$B:$S,MATCH(mtype,'Type Chart'!$A:$A,0),MATCH(XLOOKUP('Boss Editor'!$C$4,'Pokemon Editor'!$A:$A,'Pokemon Editor'!$D:$D,""),'Type Chart'!$B$1:$S$1,0)))),base,IF(OR(cat="Status",pow=0),0,FLOOR(FLOOR(FLOOR((2*$L5/5+2)*pow*atk/def)/50)+2)),modifier,stab*eff,FLOOR(base*modifier)),0) | W5: =IFERROR(LET(mtype,XLOOKUP($D5,'Move Editor'!$B:$B,'Move Editor'!$C:$C,""),cat,XLOOKUP($D5,'Move Editor'!$B:$B,'Move Editor'!$D:$D,""),pow,XLOOKUP($D5,'Move Editor'!$B:$B,'Move Editor'!$E:$E,0),acc,XLOOKUP($D5,'Move Editor'!$B:$B,'Move Editor'!$F:$F,100),atk,IF(cat="Physical",FLOOR((FLOOR(((2*XLOOKUP('Boss Editor'!$C$4,'Pokemon Editor'!$A:$A,'Pokemon Editor'!$F:$F,0)+31+FLOOR('Boss Editor'!$H$4/4))*'Boss Editor'!$D$4)/100)+5)*XLOOKUP('Boss Editor'!$E$4,'Nature Editor'!$A:$A,'Nature Editor'!$B:$B,1)),FLOOR((FLOOR(((2*XLOOKUP('Boss Editor'!$C$4,'Pokemon Editor'!$A:$A,'Pokemon Editor'!$H:$H,0)+31+FLOOR('Boss Editor'!$J$4/4))*'Boss Editor'!$D$4)/100)+5)*XLOOKUP('Boss Editor'!$E$4,'Nature Editor'!$A:$A,'Nature Editor'!$D:$D,1))),def,IF(cat="Physical",FLOOR((FLOOR(((2*XLOOKUP($K5,'Pokemon Editor'!$A:$A,'Pokemon Editor'!$G:$G,0)+31+FLOOR($Q5/4))*$L5)/100)+5)*XLOOKUP($M5,'Nature Editor'!$A:$A,'Nature Editor'!$C:$C,1)),FLOOR((FLOOR(((2*XLOOKUP($K5,'Pokemon Editor'!$A:$A,'Pokemon Editor'!$I:$I,0)+31+FLOOR($S5/4))*$L5)/100)+5)*XLOOKUP($M5,'Nature Editor'!$A:$A,'Nature Editor'!$E:$E,1))),stab,IF(OR(mtype=XLOOKUP('Boss Editor'!$C$4,'Pokemon Editor'!$A:$A,'Pokemon Editor'!$C:$C,""),mtype=XLOOKUP('Boss Editor'!$C$4,'Pokemon Editor'!$A:$A,'Pokemon Editor'!$D:$D,"")),1.5,1),eff,(INDEX('Type Chart'!$B:$S,MATCH(mtype,'Type Chart'!$A:$A,0),MATCH(XLOOKUP($K5,'Pokemon Editor'!$A:$A,'Pokemon Editor'!$C:$C,""),'Type Chart'!$B$1:$S$1,0))*IF(XLOOKUP($K5,'Pokemon Editor'!$A:$A,'Pokemon Editor'!$D:$D,"")="",1,INDEX('Type Chart'!$B:$S,MATCH(mtype,'Type Chart'!$A:$A,0),MATCH(XLOOKUP($K5,'Pokemon Editor'!$A:$A,'Pokemon Editor'!$D:$D,""),'Type Chart'!$B$1:$S$1,0)))),base,IF(OR(cat="Status",pow=0),0,FLOOR(FLOOR(FLOOR((2*'Boss Editor'!$D$4/5+2)*pow*atk/def)/50)+2)),modifier,stab*eff,FLOOR(base*modifier*0.85)),0) | X5: =IFERROR(LET(mtype,XLOOKUP($D5,'Move Editor'!$B:$B,'Move Editor'!$C:$C,""),cat,XLOOKUP($D5,'Move Editor'!$B:$B,'Move Editor'!$D:$D,""),pow,XLOOKUP($D5,'Move Editor'!$B:$B,'Move Editor'!$E:$E,0),acc,XLOOKUP($D5,'Move Editor'!$B:$B,'Move Editor'!$F:$F,100),atk,IF(cat="Physical",FLOOR((FLOOR(((2*XLOOKUP('Boss Editor'!$C$4,'Pokemon Editor'!$A:$A,'Pokemon Editor'!$F:$F,0)+31+FLOOR('Boss Editor'!$H$4/4))*'Boss Editor'!$D$4)/100)+5)*XLOOKUP('Boss Editor'!$E$4,'Nature Editor'!$A:$A,'Nature Editor'!$B:$B,1)),FLOOR((FLOOR(((2*XLOOKUP('Boss Editor'!$C$4,'Pokemon Editor'!$A:$A,'Pokemon Editor'!$H:$H,0)+31+FLOOR('Boss Editor'!$J$4/4))*'Boss Editor'!$D$4)/100)+5)*XLOOKUP('Boss Editor'!$E$4,'Nature Editor'!$A:$A,'Nature Editor'!$D:$D,1))),def,IF(cat="Physical",FLOOR((FLOOR(((2*XLOOKUP($K5,'Pokemon Editor'!$A:$A,'Pokemon Editor'!$G:$G,0)+31+FLOOR($Q5/4))*$L5)/100)+5)*XLOOKUP($M5,'Nature Editor'!$A:$A,'Nature Editor'!$C:$C,1)),FLOOR((FLOOR(((2*XLOOKUP($K5,'Pokemon Editor'!$A:$A,'Pokemon Editor'!$I:$I,0)+31+FLOOR($S5/4))*$L5)/100)+5)*XLOOKUP($M5,'Nature Editor'!$A:$A,'Nature Editor'!$E:$E,1))),stab,IF(OR(mtype=XLOOKUP('Boss Editor'!$C$4,'Pokemon Editor'!$A:$A,'Pokemon Editor'!$C:$C,""),mtype=XLOOKUP('Boss Editor'!$C$4,'Pokemon Editor'!$A:$A,'Pokemon Editor'!$D:$D,"")),1.5,1),eff,(INDEX('Type Chart'!$B:$S,MATCH(mtype,'Type Chart'!$A:$A,0),MATCH(XLOOKUP($K5,'Pokemon Editor'!$A:$A,'Pokemon Editor'!$C:$C,""),'Type Chart'!$B$1:$S$1,0))*IF(XLOOKUP($K5,'Pokemon Editor'!$A:$A,'Pokemon Editor'!$D:$D,"")="",1,INDEX('Type Chart'!$B:$S,MATCH(mtype,'Type Chart'!$A:$A,0),MATCH(XLOOKUP($K5,'Pokemon Editor'!$A:$A,'Pokemon Editor'!$D:$D,""),'Type Chart'!$B$1:$S$1,0)))),base,IF(OR(cat="Status",pow=0),0,FLOOR(FLOOR(FLOOR((2*'Boss Editor'!$D$4/5+2)*pow*atk/def)/50)+2)),modifier,stab*eff,FLOOR(base*modifier)),0) | Y5: SPECIES_SEWADDLE
